Workbook
Name Aircraft_ID: tblAircraft[Aircraft ID]
Name AircraftIDs: tblAircraft[Aircraft ID]
Name Avionics_Evaluation_ID: tblAvionicsEvaluations[Avionics Evaluation ID]
Name Avionics_Evaluation_Source_ID: tblAvionicsEvaluationSources[Avionics Evaluation Source ID]
Name Avionics_Evidence_Role: 'Documentation '!$I$21:$I$23
Name Avionics_ID: tblAvionics[Avionics ID]
Name Avionics_Type: 'Documentation '!$I$3:$I$12
Name Configuration_Avionics_ID: tblConfigurationAvionics[Configuration Avionics ID]
Name Configuration_ID: tblAircraftConfigurations[Configuration ID]
Name Engine_ID: tblEngines[Engine_ID]
Name Evaluation_ID: tblSystemsDepth[Evaluation ID]
Name Evaluation_Scope: 'Documentation '!$E$21:$E$23
Name Evidence_Scope: 'Documentation '!$C$21:$C$25
Name Manufacturer_ID: tblManufacturers[Manufacturers ID]
Name Source_ID: tblSources[Source ID]
Name Variant_ID: tblAircraftVariants[Variant ID]

Sheet Dashboard 
A1: FSEI DASHBOARD
A3: Overall ranking
A4: Simulator | B4: Score | C4: Rank
A5: MSFS 2024 | B5: =Scoring_engine!J4 -> 92.55 | C5: =_xlfn.RANK.EQ(B5,$B$5:$B$7,0) -> 1
A6: XPlane 12 | B6: =Scoring_engine!J5 -> 92 | C6: =_xlfn.RANK.EQ(B6,$B$5:$B$7,0) -> 2
A7: P3D | B7: =Scoring_engine!J6 -> 66.35 | C7: =_xlfn.RANK.EQ(B7,$B$5:$B$7,0) -> 3

Sheet ---- MANUFACTURERS ----

Sheet Manufacturers_DB
A1: FSEI Manufacturer's Database
A3: Manufacturers ID | B3: Manfacturer
A4: 1 | B4: Boeing
A5: 2 | B5: Cirrus Aircraft
A6: 3 | B6: Diamond Aircraft
A7: 4 | B7: Airbus

Sheet ---- AIRCRAFT ----

Sheet Aircraft-db
A1: FSEI Aircraft Database
A3: Aircraft ID | B3: Manufacturer ID | C3: Variant ID | D3: Aircraft | E3: Simulator | F3: Developer | G3: Aircraft Type | H3: Systems Depth | I3: Flight Model Quality | J3: Update Frequency | K3: User Rating | L3: Release Date | M3: Status | N3: Source | O3: Last Updated | P3: Update Method | Q3: Update Tool | R3: Updater Generation | S3: Notes
A4: 1 | B4: 1 | D4: 777 | E4: X-Plane 12 | F4: FlightFactor | G4: Airliner | H4: =_xlfn.XLOOKUP(tblAircraft[[#This Row],[Aircraft ID]],tblSystemsDepth[Aircraft ID],tblSystemsDepth[Systems Depth Score],"") -> 97 | M4: Active | P4: X-Updater
A5: 2 | B5: 2 | D5: SR20 | E5: X-Plane 12 | F5: TorqueSim | G5: General Aviation | H5: =_xlfn.XLOOKUP(tblAircraft[[#This Row],[Aircraft ID]],tblSystemsDepth[Aircraft ID],tblSystemsDepth[Systems Depth Score],"") -> 98 | M5: Active
A6: 3 | B6: 3 | D6: DA50 | E6: X-Plane 12 | F6: Aerobask | G6: General Aviation | H6: =_xlfn.XLOOKUP(tblAircraft[[#This Row],[Aircraft ID]],tblSystemsDepth[Aircraft ID],tblSystemsDepth[Systems Depth Score],"") -> 94
A7: 4 | B7: 4 | C7: 6 | D7: A321 | E7: X-Plane 12 | F7: Toliss | G7: Airliner | H7: =_xlfn.XLOOKUP(tblAircraft[[#This Row],[Aircraft ID]],tblSystemsDepth[Aircraft ID],tblSystemsDepth[Systems Depth Score],"") -> 97

Sheet Aircraft_Variants
A1: FSEI Aircraft Variants Database
A3: Variant ID | B3: Aircraft ID | C3: Aircraft | D3: Simulator | E3: Variant | F3: Notes
A4: 1 | B4: 1 | C4: =_xlfn.XLOOKUP(B4,tblAircraft[Aircraft ID],tblAircraft[Aircraft],"") -> 777 | D4: =_xlfn.XLOOKUP(B4,tblAircraft[Aircraft ID],tblAircraft[Simulator],"") -> X-Plane 12 | E4: 777-200ER
A5: 2 | B5: 1 | C5: =_xlfn.XLOOKUP(B5,tblAircraft[Aircraft ID],tblAircraft[Aircraft],"") -> 777 | D5: =_xlfn.XLOOKUP(B5,tblAircraft[Aircraft ID],tblAircraft[Simulator],"") -> X-Plane 12 | E5: 777-300ER
A6: 3 | B6: 1 | C6: =_xlfn.XLOOKUP(B6,tblAircraft[Aircraft ID],tblAircraft[Aircraft],"") -> 777 | D6: =_xlfn.XLOOKUP(B6,tblAircraft[Aircraft ID],tblAircraft[Simulator],"") -> X-Plane 12 | E6: 777F
A7: 4 | B7: 2 | C7: =_xlfn.XLOOKUP(B7,tblAircraft[Aircraft ID],tblAircraft[Aircraft],"") -> SR20 | D7: =_xlfn.XLOOKUP(B7,tblAircraft[Aircraft ID],tblAircraft[Simulator],"") -> X-Plane 12 | E7: SR20 G3 | F7: G3-generation Cirrus SR20 modeled by TorqueSim; evaluated in X-Plane 12. Equipped with Garmin Perspective avionics configuration.
A8: 5 | B8: 3 | C8: =_xlfn.XLOOKUP(B8,tblAircraft[Aircraft ID],tblAircraft[Aircraft],"") -> DA50 | D8: =_xlfn.XLOOKUP(B8,tblAircraft[Aircraft ID],tblAircraft[Simulator],"") -> X-Plane 12 | E8: DA50 RG | F8: Aerobask Diamond DA50 RG modeled for X-Plane 12.
A9: 6 | B9: 4 | C9: =_xlfn.XLOOKUP(B9,tblAircraft[Aircraft ID],tblAircraft[Aircraft],"") -> A321 | D9: =_xlfn.XLOOKUP(B9,tblAircraft[Aircraft ID],tblAircraft[Simulator],"") -> X-Plane 12 | E9: A321-200 | F9: ToLiss Airbus A321-200 modeled for X-Plane 12; evaluated using a complete KCLT–KLAF flight.

Sheet Engines_DB
A1: FSEI Engines Database
A3: Engine_ID | B3: Manufacturer | C3: Engine Model | D3: Engine Type | E3: Notes
A4: 1 | B4: GE | C4: GE90-90B | D4: Turbofan | E4: Used in the 777-200ER
A5: 2 | B5: GE | C5: GE90-115BL | D5: Turbofan | E5: Used in the 777-300ER
A6: 3 | B6: GE | C6: GE90-110B1L | D6: Turbofan | E6: Used in the 777F
A7: 4 | B7: Teledyne Continental | C7: IO-360-ES | D7: Piston | E7: Used in the Cirrus SR20
A8: 5 | B8: Continental Aerospace Technologies | C8: CD-300 | D8: Turbodiesel | E8: Continental CD-300, 300 hp, six-cylinder, liquid-cooled, turbocharged, FADEC-controlled aircraft diesel engine used in the Aerobask Diamond DA50 RG.

Sheet Variant-Engines
A1: FSEI Variant Engine Database
A3: Variant Engine ID | B3: Variant ID | C3: Engine ID | D3: Variant | E3: Engine Model | F3: Notes
A4: 1 | B4: 1 | C4: 1 | D4: =_xlfn.XLOOKUP(tblVariantEngines[[#This Row],[Variant ID]],tblAircraftVariants[Variant ID],tblAircraftVariants[Variant],"") -> 777-200ER | E4: =_xlfn.XLOOKUP(C4,Engines_DB!$A$4:$A$100,Engines_DB!$C$4:$C$100,"") -> GE90-90B
A5: 2 | B5: 2 | C5: 2 | D5: =_xlfn.XLOOKUP(tblVariantEngines[[#This Row],[Variant ID]],tblAircraftVariants[Variant ID],tblAircraftVariants[Variant],"") -> 777-300ER | E5: =_xlfn.XLOOKUP(C5,Engines_DB!$A$4:$A$100,Engines_DB!$C$4:$C$100,"") -> GE90-115BL
A6: 3 | B6: 3 | C6: 3 | D6: =_xlfn.XLOOKUP(tblVariantEngines[[#This Row],[Variant ID]],tblAircraftVariants[Variant ID],tblAircraftVariants[Variant],"") -> 777F | E6: =_xlfn.XLOOKUP(C6,Engines_DB!$A$4:$A$100,Engines_DB!$C$4:$C$100,"") -> GE90-110B1L
A7: 4 | B7: 4 | C7: 4 | D7: =_xlfn.XLOOKUP(tblVariantEngines[[#This Row],[Variant ID]],tblAircraftVariants[Variant ID],tblAircraftVariants[Variant],"") -> SR20 G3 | E7: =_xlfn.XLOOKUP(C7,Engines_DB!$A$4:$A$100,Engines_DB!$C$4:$C$100,"") -> IO-360-ES
A8: 5 | B8: 5 | C8: 5 | D8: =_xlfn.XLOOKUP(tblVariantEngines[[#This Row],[Variant ID]],tblAircraftVariants[Variant ID],tblAircraftVariants[Variant],"") -> DA50 RG | E8: =_xlfn.XLOOKUP(C8,Engines_DB!$A$4:$A$100,Engines_DB!$C$4:$C$100,"") -> CD-300

Sheet Aircraft_Configurations
A1: FSEI Aircraft Configurations
A3: Configuration ID | B3: Variant ID | C3: Aircraft ID | D3: Aircraft | E3: Simulator | F3: Configuration Name | G3: Notes
A4: 1 | B4: 1 | C4: =IF(tblAircraftConfigurations[[#This Row],[Variant ID]]="","",_xlfn.XLOOKUP(tblAircraftConfigurations[[#This Row],[Variant ID]],tblAircraftVariants[Variant ID],tblAircraftVariants[Aircraft ID],"")) -> 1 | D4: =IF(tblAircraftConfigurations[[#This Row],[Aircraft ID]]="","",_xlfn.XLOOKUP(tblAircraftConfigurations[[#This Row],[Aircraft ID]],tblAircraft[Aircraft ID],tblAircraft[Aircraft],"")) -> 777 | E4: =IF(tblAircraftConfigurations[[#This Row],[Aircraft ID]]="","",_xlfn.XLOOKUP(tblAircraftConfigurations[[#This Row],[Aircraft ID]],tblAircraft[Aircraft ID],tblAircraft[Simulator],"")) -> X-Plane 12 | F4: 777-200ER Standard Configuration
A5: 2 | B5: 4 | C5: =IF(tblAircraftConfigurations[[#This Row],[Variant ID]]="","",_xlfn.XLOOKUP(tblAircraftConfigurations[[#This Row],[Variant ID]],tblAircraftVariants[Variant ID],tblAircraftVariants[Aircraft ID],"")) -> 2 | D5: =IF(tblAircraftConfigurations[[#This Row],[Aircraft ID]]="","",_xlfn.XLOOKUP(tblAircraftConfigurations[[#This Row],[Aircraft ID]],tblAircraft[Aircraft ID],tblAircraft[Aircraft],"")) -> SR20 | E5: =IF(tblAircraftConfigurations[[#This Row],[Aircraft ID]]="","",_xlfn.XLOOKUP(tblAircraftConfigurations[[#This Row],[Aircraft ID]],tblAircraft[Aircraft ID],tblAircraft[Simulator],"")) -> X-Plane 12 | F5: SR20 G3 Perspective | G5: TorqueSim SR20 G3 configuration equipped with Garmin Perspective avionics; evaluated in X-Plane 12.
A6: 3 | B6: 5 | C6: =IF(tblAircraftConfigurations[[#This Row],[Variant ID]]="","",_xlfn.XLOOKUP(tblAircraftConfigurations[[#This Row],[Variant ID]],tblAircraftVariants[Variant ID],tblAircraftVariants[Aircraft ID],"")) -> 3 | D6: =IF(tblAircraftConfigurations[[#This Row],[Aircraft ID]]="","",_xlfn.XLOOKUP(tblAircraftConfigurations[[#This Row],[Aircraft ID]],tblAircraft[Aircraft ID],tblAircraft[Aircraft],"")) -> DA50 | E6: =IF(tblAircraftConfigurations[[#This Row],[Aircraft ID]]="","",_xlfn.XLOOKUP(tblAircraftConfigurations[[#This Row],[Aircraft ID]],tblAircraft[Aircraft ID],tblAircraft[Simulator],"")) -> X-Plane 12 | F6: DA50 RG G1000 | G6: Aerobask Diamond DA50 RG configuration equipped with integrated Garmin G1000/X1000 avionics; evaluated in X-Plane 12.
A7: 4 | B7: 6 | C7: =IF(tblAircraftConfigurations[[#This Row],[Variant ID]]="","",_xlfn.XLOOKUP(tblAircraftConfigurations[[#This Row],[Variant ID]],tblAircraftVariants[Variant ID],tblAircraftVariants[Aircraft ID],"")) -> 4 | D7: =IF(tblAircraftConfigurations[[#This Row],[Aircraft ID]]="","",_xlfn.XLOOKUP(tblAircraftConfigurations[[#This Row],[Aircraft ID]],tblAircraft[Aircraft ID],tblAircraft[Aircraft],"")) -> A321 | E7: =IF(tblAircraftConfigurations[[#This Row],[Aircraft ID]]="","",_xlfn.XLOOKUP(tblAircraftConfigurations[[#This Row],[Aircraft ID]],tblAircraft[Aircraft ID],tblAircraft[Simulator],"")) -> X-Plane 12 | F7: A321-200 Standard Configuration | G7: ToLiss A321-200 standard configuration evaluated in X-Plane 12 using a complete KCLT-KLAF flight.

Sheet Systems_Depth
A1: FSEI Systems Depth Database
A3: Evaluation ID | B3: Evaluation Sope | C3: Aircraft ID | D3: Variant ID | E3: Variant | F3: Aircraft | G3: Simulator | H3: Electrical Systems | I3: Hydraulic / Pneumatic Systems | J3: FMS / Navigation Depth | K3: Failures / Abnormal Procedures | L3: Procedural Fidelity | M3: Systems Depth Score | N3: Date Verified
A4: 1 | C4: 1 | E4: =IF(tblSystemsDepth[[#This Row],[Variant ID]]="","",_xlfn.XLOOKUP(tblSystemsDepth[[#This Row],[Variant ID]],tblAircraftVariants[Variant ID],tblAircraftVariants[Variant],"")) | F4: =_xlfn.XLOOKUP(tblSystemsDepth[[#This Row],[Aircraft ID]],tblAircraft[Aircraft ID],tblAircraft[Aircraft],"") -> 777 | G4: =_xlfn.XLOOKUP(tblSystemsDepth[[#This Row],[Aircraft ID]],tblAircraft[Aircraft ID],tblAircraft[Simulator],"") -> X-Plane 12 | H4: 19 | I4: 19 | J4: 20 | K4: 19 | L4: 20 | M4: =IF(COUNT(tblSystemsDepth[[#This Row],[Electrical Systems]]:tblSystemsDepth[[#This Row],[Procedural Fidelity]])=0,"",ROUND(SUM(tblSystemsDepth[[#This Row],[Electrical Systems]]:tblSystemsDepth[[#This Row],[Procedural Fidelity]])/(COUNT(tblSystemsDepth[[#This Row],[Electrical Systems]]:tblSystemsDepth[[#This Row],[Procedural Fidelity]])*20)*100,0)) -> 97 | N4: 46274
A5: 2 | B5: Variant | C5: 2 | D5: 4 | E5: =IF(tblSystemsDepth[[#This Row],[Variant ID]]="","",_xlfn.XLOOKUP(tblSystemsDepth[[#This Row],[Variant ID]],tblAircraftVariants[Variant ID],tblAircraftVariants[Variant],"")) -> SR20 G3 | F5: =_xlfn.XLOOKUP(tblSystemsDepth[[#This Row],[Aircraft ID]],tblAircraft[Aircraft ID],tblAircraft[Aircraft],"") -> SR20 | G5: =_xlfn.XLOOKUP(tblSystemsDepth[[#This Row],[Aircraft ID]],tblAircraft[Aircraft ID],tblAircraft[Simulator],"") -> X-Plane 12 | H5: 20 | I5: 19 | J5: 20 | K5: 20 | L5: 19 | M5: =IF(COUNT(tblSystemsDepth[[#This Row],[Electrical Systems]]:tblSystemsDepth[[#This Row],[Procedural Fidelity]])=0,"",ROUND(SUM(tblSystemsDepth[[#This Row],[Electrical Systems]]:tblSystemsDepth[[#This Row],[Procedural Fidelity]])/(COUNT(tblSystemsDepth[[#This Row],[Electrical Systems]]:tblSystemsDepth[[#This Row],[Procedural Fidelity]])*20)*100,0)) -> 98 | N5: 46275
A6: 3 | B6: Variant | C6: 3 | D6: 5 | E6: =IF(tblSystemsDepth[[#This Row],[Variant ID]]="","",_xlfn.XLOOKUP(tblSystemsDepth[[#This Row],[Variant ID]],tblAircraftVariants[Variant ID],tblAircraftVariants[Variant],"")) -> DA50 RG | F6: =_xlfn.XLOOKUP(tblSystemsDepth[[#This Row],[Aircraft ID]],tblAircraft[Aircraft ID],tblAircraft[Aircraft],"") -> DA50 | G6: =_xlfn.XLOOKUP(tblSystemsDepth[[#This Row],[Aircraft ID]],tblAircraft[Aircraft ID],tblAircraft[Simulator],"") -> X-Plane 12 | H6: 19 | I6: 19 | J6: 20 | K6: 18 | L6: 18 | M6: =IF(COUNT(tblSystemsDepth[[#This Row],[Electrical Systems]]:tblSystemsDepth[[#This Row],[Procedural Fidelity]])=0,"",ROUND(SUM(tblSystemsDepth[[#This Row],[Electrical Systems]]:tblSystemsDepth[[#This Row],[Procedural Fidelity]])/(COUNT(tblSystemsDepth[[#This Row],[Electrical Systems]]:tblSystemsDepth[[#This Row],[Procedural Fidelity]])*20)*100,0)) -> 94 | N6: 46276
A7: 4 | B7: Variant | C7: 4 | D7: 6 | E7: =IF(tblSystemsDepth[[#This Row],[Variant ID]]="","",_xlfn.XLOOKUP(tblSystemsDepth[[#This Row],[Variant ID]],tblAircraftVariants[Variant ID],tblAircraftVariants[Variant],"")) -> A321-200 | F7: =_xlfn.XLOOKUP(tblSystemsDepth[[#This Row],[Aircraft ID]],tblAircraft[Aircraft ID],tblAircraft[Aircraft],"") -> A321 | G7: =_xlfn.XLOOKUP(tblSystemsDepth[[#This Row],[Aircraft ID]],tblAircraft[Aircraft ID],tblAircraft[Simulator],"") -> X-Plane 12 | H7: 19 | I7: 19 | J7: 20 | K7: 19 | L7: 20 | M7: =IF(COUNT(tblSystemsDepth[[#This Row],[Electrical Systems]]:tblSystemsDepth[[#This Row],[Procedural Fidelity]])=0,"",ROUND(SUM(tblSystemsDepth[[#This Row],[Electrical Systems]]:tblSystemsDepth[[#This Row],[Procedural Fidelity]])/(COUNT(tblSystemsDepth[[#This Row],[Electrical Systems]]:tblSystemsDepth[[#This Row],[Procedural Fidelity]])*20)*100,0)) -> 97 | N7: 46280

Sheet Evaluation_Sources
A1: FSEI Evaluation Sources Database
A3: Evaluation Source ID | B3: Evaluation ID | C3: Source ID | D3: Aircraft | E3: Source Name | F3: Evidence Role | G3: Notes
A4: 1 | B4: 1 | C4: 2 | D4: =_xlfn.XLOOKUP(tblEvaluationSources[[#This Row],[Evaluation ID]],tblSystemsDepth[Evaluation ID],tblSystemsDepth[Aircraft],"") -> 777 | E4: =_xlfn.XLOOKUP(tblEvaluationSources[[#This Row],[Source ID]],tblSources[Source ID],tblSources[Source Name],"") -> FlightFactor 777 Ultimate Introduction Bulletin | F4: Supporting | G4: General FlightFactor 777 product/manual documentation
A5: 2 | B5: 1 | C5: 6 | D5: =_xlfn.XLOOKUP(tblEvaluationSources[[#This Row],[Evaluation ID]],tblSystemsDepth[Evaluation ID],tblSystemsDepth[Aircraft],"") -> 777 | E5: =_xlfn.XLOOKUP(tblEvaluationSources[[#This Row],[Source ID]],tblSources[Source ID],tblSources[Source Name],"") -> FlightFactor 777 Systems Manual | F5: Primary | G5: Primary technical systems documentation
A6: 3 | B6: 1 | C6: 7 | D6: =_xlfn.XLOOKUP(tblEvaluationSources[[#This Row],[Evaluation ID]],tblSystemsDepth[Evaluation ID],tblSystemsDepth[Aircraft],"") -> 777 | E6: =_xlfn.XLOOKUP(tblEvaluationSources[[#This Row],[Source ID]],tblSources[Source ID],tblSources[Source Name],"") -> FlightFactor 777 Cockpit Guide | F6: Supporting | G6: Cockpit controls, displays, indications, and system interfaces
A7: 4 | B7: 1 | C7: 8 | D7: =_xlfn.XLOOKUP(tblEvaluationSources[[#This Row],[Evaluation ID]],tblSystemsDepth[Evaluation ID],tblSystemsDepth[Aircraft],"") -> 777 | E7: =_xlfn.XLOOKUP(tblEvaluationSources[[#This Row],[Source ID]],tblSources[Source ID],tblSources[Source Name],"") -> FlightFactor 777 Automatic Interactive Procedures | F7: Supporting | G7: Procedural implementation and crew-interaction evidence
A8: 5 | B8: 2 | C8: 11 | D8: =_xlfn.XLOOKUP(tblEvaluationSources[[#This Row],[Evaluation ID]],tblSystemsDepth[Evaluation ID],tblSystemsDepth[Aircraft],"") -> SR20 | E8: =_xlfn.XLOOKUP(tblEvaluationSources[[#This Row],[Source ID]],tblSources[Source ID],tblSources[Source Name],"") -> TorqueSim SR20 Airplane Information Manual | F8: Primary | G8: Primary aircraft documentation supporting the SR20 G3 Systems Depth evaluation, including electrical architecture, aircraft systems, normal and emergency procedures, failure behavior, and modeled system interactions.
A9: 6 | B9: 2 | C9: 12 | D9: =_xlfn.XLOOKUP(tblEvaluationSources[[#This Row],[Evaluation ID]],tblSystemsDepth[Evaluation ID],tblSystemsDepth[Aircraft],"") -> SR20 | E9: =_xlfn.XLOOKUP(tblEvaluationSources[[#This Row],[Source ID]],tblSources[Source ID],tblSources[Source Name],"") -> TorqueSim SR20 Garmin Perspective Direct Testing | F9: Direct Testing | G9: Direct hands-on testing supporting the SR20 G3 Systems Depth evaluation, including electrical and circuit-breaker interactions, system annunciations, normal IFR operations, abnormal behavior, navigation/heading degradation, and RNAV approach operations.
A10: 7 | B10: 3 | C10: 13 | D10: =_xlfn.XLOOKUP(tblEvaluationSources[[#This Row],[Evaluation ID]],tblSystemsDepth[Evaluation ID],tblSystemsDepth[Aircraft],"") -> DA50 | E10: =_xlfn.XLOOKUP(tblEvaluationSources[[#This Row],[Source ID]],tblSources[Source ID],tblSources[Source Name],"") -> Aerobask Diamond DA50 RG Aircraft Flight Manual
A11: 8 | B11: 3 | C11: 14 | D11: =_xlfn.XLOOKUP(tblEvaluationSources[[#This Row],[Evaluation ID]],tblSystemsDepth[Evaluation ID],tblSystemsDepth[Aircraft],"") -> DA50 | E11: =_xlfn.XLOOKUP(tblEvaluationSources[[#This Row],[Source ID]],tblSources[Source ID],tblSources[Source Name],"") -> Aerobask DA50 RG Direct Testing
A12: 9 | B12: 4 | C12: 17 | D12: =_xlfn.XLOOKUP(tblEvaluationSources[[#This Row],[Evaluation ID]],tblSystemsDepth[Evaluation ID],tblSystemsDepth[Aircraft],"") -> A321 | E12: =_xlfn.XLOOKUP(tblEvaluationSources[[#This Row],[Source ID]],tblSources[Source ID],tblSources[Source Name],"") -> ToLiss A321 Direct Flight Evaluation | F12: Primary | G12: Primary evidence from complete KCLT–KLAF flight evaluation of the ToLiss A321-200 in X-Plane 12.
A13: 10 | B13: 4 | C13: 18 | D13: =_xlfn.XLOOKUP(tblEvaluationSources[[#This Row],[Evaluation ID]],tblSystemsDepth[Evaluation ID],tblSystemsDepth[Aircraft],"") -> A321 | E13: =_xlfn.XLOOKUP(tblEvaluationSources[[#This Row],[Source ID]],tblSources[Source ID],tblSources[Source Name],"") -> ToLiss A321 Developer Documentation | F13: Supporting | G13: Official ToLiss documentation supporting systems depth, failure simulation, FMS/navigation, and procedural fidelity observed during the A321 evaluation.

Sheet ---- AVIONICS ----

Sheet Avionics_DB
A1: FSEI Avionics
A3: Avionics ID | B3: Developer / Manufacturer | C3: Avionics Type | D3: System / Model | E3: Version / Generation | F3: Notes
A4: 1 | B4: FlightFactor / StepToSky | C4: EFB | D4: FlightFactor EFB | F4: Integrated electronic flight bag implementation for the FlightFactor 777.
A5: 2 | B5: Garmin | C5: PFD / ND | D5: Garmin Perspective | E5: Perspective (G3) | F5: Garmin Perspective integrated avionics suite installed in the TorqueSim SR20 G3 configuration; evaluated in X-Plane 12.
A6: 3 | B6: Garmin | C6: PFD / ND | D6: Garmin G1000 / X1000 | F6: Integrated Garmin G1000-based avionics suite implemented using a customized Laminar Research X1000 system in the Aerobask Diamond DA50 RG; evaluated in X-Plane 12.
A7: 4 | B7: Boeing | C7: FMS / FMC | D7: 777 Flight Management System (FMS/FMC) | F7: Boeing 777 flight management system implemented in the FlightFactor 777v2. Includes flight planning, route management, performance initialization, navigation, VNAV/LNAV functions, and CDU-based pilot interaction; fidelity to be evaluated separately from the EFB.
A8: 5 | B8: Boeing | C8: PFD / ND | D8: 777 Primary Flight & Navigation Display System | F8: Boeing 777 captain and first-officer primary flight and navigation display system implemented in the FlightFactor 777v2. Includes duplicated PFD/ND presentation and associated flight, navigation, guidance, mode, and situational-awareness information. Evaluated separately from center multifunction/display functions, FMS/FMC, autoflight, and EFB systems.
A9: 6 | B9: Boeing | C9: Multifunction Display | D9: 777 Center Multifunction Display System | F9: Boeing 777 center multifunction/display system implemented in the FlightFactor 777v2. Supports communications management, ATC functions, ACARS/datalink, electronic checklist, and other center-display functions. Evaluated separately from the PFD/ND, FMS/FMC, autoflight, and EFB systems.
A10: 7 | B10: Boeing | C10: Autopilot / Flight Director | D10: 777 Autoflight / Flight Director System | F10: Boeing 777 autoflight system implemented in the FlightFactor 777v2. Includes autopilot, flight director, autothrottle, LNAV/VNAV execution, lateral and vertical mode logic, mode annunciation, altitude and course capture, approach guidance, and associated autoflight functions.
A11: 8 | B11: Airbus | C11: FMS / FMC | D11: Airbus A321 Flight Management and Guidance System (FMGS) | F11: Airbus A321 FMGS implemented in the ToLiss A321, supporting flight-plan management, performance initialization, managed/selected guidance, SID/STAR procedures, wind data uplink, and navigation functions.
A12: 9 | B12: ToLiss | C12: Autopilot / Flight Director | D12: Airbus A321 Autopilot / Flight Director System | F12: ToLiss implementation of the Airbus A321 autoflight and flight director system, supporting managed and selected guidance, autopilot operation, flight director commands, and approach/landing guidance.
A13: 10 | B13: ToLiss | C13: PFD / ND | D13: Airbus A321 Primary Flight / Navigation Display System | F13: ToLiss implementation of the Airbus A321 PFD and ND system, providing primary flight parameters, flight guidance, navigation routing, managed/selected modes, and approach/navigation information.
A14: 11 | B14: ToLiss | C14: Multifunction Display | D14: Airbus A321 ECAM Engine Warning / System Display System | F14: ToLiss implementation of the Airbus A321 ECAM EWD/SD system, providing engine and warning information, aircraft system status, and system synoptic displays.
A15: 12 | B15: ToLiss | C15: ACARS / CPDLC | D15: Airbus A321 ACARS / CPDLC System | F15: ToLiss implementation of Airbus A321 ACARS/CPDLC functions, supporting digital ATC communications, AOC messaging, flight-plan data exchange, and operational information services.
A16: 13 | B16: ToLiss | C16: EFB | D16: ToLiss A321 Electronic Flight Bag (EFB) | F16: Integrated ToLiss A321 EFB supporting SimBrief OFP integration, weight and balance, takeoff and landing performance, ground services, aircraft configuration, fault scenarios, checklists, and AviTab integration.
A17: 14 | B17: ToLiss | C17: Weather Radar | D17: Airbus A321 Weather Radar System | F17: ToLiss implementation of the Airbus A321 weather radar system, providing weather radar information displayed on the Navigation Display with pilot-controlled weather image intensity.
... A20: 17 | B20: ToLiss | C20: GPS / Navigation | D20: Airbus A321 GPS / Navigation System | F20: ToLiss implementation of the Airbus A321 navigation system, supporting GPS-based aircraft positioning, flight-plan navigation, waypoint sequencing, radio navigation, and managed lateral navigation through the FMGS.

Sheet Configuration_Avionics
A1: FSEI Configuration Avionics
A3: Configuration Avionics ID | B3: Configuration ID | C3: Avionics ID | D3: Configuration Name | E3: Avionics System | F3: Avionics Role | G3: Notes
A4: 1 | B4: 1 | C4: 1 | D4: =_xlfn.XLOOKUP(tblConfigurationAvionics[[#This Row],[Configuration ID]],tblAircraftConfigurations[Configuration ID],tblAircraftConfigurations[Configuration Name],"") -> 777-200ER Standard Configuration | E4: =_xlfn.XLOOKUP(tblConfigurationAvionics[[#This Row],[Avionics ID]],tblAvionics[Avionics ID],tblAvionics[System / Model],"") -> FlightFactor EFB | F4: Primary EFB
A5: 2 | B5: 2 | C5: 2 | D5: =_xlfn.XLOOKUP(tblConfigurationAvionics[[#This Row],[Configuration ID]],tblAircraftConfigurations[Configuration ID],tblAircraftConfigurations[Configuration Name],"") -> SR20 G3 Perspective | E5: =_xlfn.XLOOKUP(tblConfigurationAvionics[[#This Row],[Avionics ID]],tblAvionics[Avionics ID],tblAvionics[System / Model],"") -> Garmin Perspective | F5: Primary Intergrated Avionics Suite | G5: Primary Garmin Perspective avionics suite for the TorqueSim SR20 G3 configuration.
A6: 3 | B6: 3 | C6: 3 | D6: =_xlfn.XLOOKUP(tblConfigurationAvionics[[#This Row],[Configuration ID]],tblAircraftConfigurations[Configuration ID],tblAircraftConfigurations[Configuration Name],"") -> DA50 RG G1000 | E6: =_xlfn.XLOOKUP(tblConfigurationAvionics[[#This Row],[Avionics ID]],tblAvionics[Avionics ID],tblAvionics[System / Model],"") -> Garmin G1000 / X1000 | F6: Primary Intergrated Avionics Suite | G6: Primary Garmin G1000/X1000 avionics suite for the Aerobask Diamond DA50 RG configuration.
A7: 4 | B7: 1 | C7: 4 | D7: =_xlfn.XLOOKUP(tblConfigurationAvionics[[#This Row],[Configuration ID]],tblAircraftConfigurations[Configuration ID],tblAircraftConfigurations[Configuration Name],"") -> 777-200ER Standard Configuration | E7: =_xlfn.XLOOKUP(tblConfigurationAvionics[[#This Row],[Avionics ID]],tblAvionics[Avionics ID],tblAvionics[System / Model],"") -> 777 Flight Management System (FMS/FMC) | F7: Primary Flight Management System | G7: Primary flight management and CDU-based navigation/performance system for the FlightFactor 777v2 configuration.
A8: 5 | B8: 1 | C8: 5 | D8: =_xlfn.XLOOKUP(tblConfigurationAvionics[[#This Row],[Configuration ID]],tblAircraftConfigurations[Configuration ID],tblAircraftConfigurations[Configuration Name],"") -> 777-200ER Standard Configuration | E8: =_xlfn.XLOOKUP(tblConfigurationAvionics[[#This Row],[Avionics ID]],tblAvionics[Avionics ID],tblAvionics[System / Model],"") -> 777 Primary Flight & Navigation Display System | F8: Primary Flight / Navigation Displays | G8: Captain and first-officer PFD/ND system for the FlightFactor 777v2.
A9: 6 | B9: 1 | C9: 6 | D9: =_xlfn.XLOOKUP(tblConfigurationAvionics[[#This Row],[Configuration ID]],tblAircraftConfigurations[Configuration ID],tblAircraftConfigurations[Configuration Name],"") -> 777-200ER Standard Configuration | E9: =_xlfn.XLOOKUP(tblConfigurationAvionics[[#This Row],[Avionics ID]],tblAvionics[Avionics ID],tblAvionics[System / Model],"") -> 777 Center Multifunction Display System | F9: Center Multifunction / Communications Display | G9: Center multifunction display functions for the FlightFactor 777v2, including communications, datalink and electronic checklist interfaces.
A10: 7 | B10: 1 | C10: 7 | D10: =_xlfn.XLOOKUP(tblConfigurationAvionics[[#This Row],[Configuration ID]],tblAircraftConfigurations[Configuration ID],tblAircraftConfigurations[Configuration Name],"") -> 777-200ER Standard Configuration | E10: =_xlfn.XLOOKUP(tblConfigurationAvionics[[#This Row],[Avionics ID]],tblAvionics[Avionics ID],tblAvionics[System / Model],"") -> 777 Autoflight / Flight Director System | F10: Primary Autoflight System | G10: Primary FlightFactor 777v2 autoflight implementation, including autopilot, flight director, autothrottle and lateral/vertical guidance execution.
A11: 8 | B11: 4 | C11: 8 | D11: =_xlfn.XLOOKUP(tblConfigurationAvionics[[#This Row],[Configuration ID]],tblAircraftConfigurations[Configuration ID],tblAircraftConfigurations[Configuration Name],"") -> A321-200 Standard Configuration | E11: =_xlfn.XLOOKUP(tblConfigurationAvionics[[#This Row],[Avionics ID]],tblAvionics[Avionics ID],tblAvionics[System / Model],"") -> Airbus A321 Flight Management and Guidance System (FMGS) | F11: Primary Flight Management System | G11: Primary Airbus A321 flight management system implemented in the ToLiss A321, supporting flight planning, performance management, navigation, and managed flight guidance.
A12: 9 | B12: 4 | C12: 9 | D12: =_xlfn.XLOOKUP(tblConfigurationAvionics[[#This Row],[Configuration ID]],tblAircraftConfigurations[Configuration ID],tblAircraftConfigurations[Configuration Name],"") -> A321-200 Standard Configuration | E12: =_xlfn.XLOOKUP(tblConfigurationAvionics[[#This Row],[Avionics ID]],tblAvionics[Avionics ID],tblAvionics[System / Model],"") -> Airbus A321 Autopilot / Flight Director System | F12: Primary Flight / Flight Navigation Systems | G12: Primary ToLiss A321 autoflight and flight guidance system, supporting managed and selected guidance, autopilot operation, flight director commands, and approach/landing guidance.
A13: 10 | B13: 4 | C13: 10 | D13: =_xlfn.XLOOKUP(tblConfigurationAvionics[[#This Row],[Configuration ID]],tblAircraftConfigurations[Configuration ID],tblAircraftConfigurations[Configuration Name],"") -> A321-200 Standard Configuration | E13: =_xlfn.XLOOKUP(tblConfigurationAvionics[[#This Row],[Avionics ID]],tblAvionics[Avionics ID],tblAvionics[System / Model],"") -> Airbus A321 Primary Flight / Navigation Display System | F13: Primary Flight & Navigation Display System | G13: Primary ToLiss A321 flight and navigation display system, providing flight parameters, flight guidance, navigation routing, managed/selected modes, and approach/navigation information.
A14: 11 | B14: 4 | C14: 11 | D14: =_xlfn.XLOOKUP(tblConfigurationAvionics[[#This Row],[Configuration ID]],tblAircraftConfigurations[Configuration ID],tblAircraftConfigurations[Configuration Name],"") -> A321-200 Standard Configuration | E14: =_xlfn.XLOOKUP(tblConfigurationAvionics[[#This Row],[Avionics ID]],tblAvionics[Avionics ID],tblAvionics[System / Model],"") -> Airbus A321 ECAM Engine Warning / System Display System | F14: Primary Aircraft Systems Monitoring & Alerting System | G14: Primary ToLiss A321 ECAM system providing engine and warning information, aircraft systems monitoring, status information, and system synoptic displays.
A15: 12 | B15: 4 | C15: 12 | D15: =_xlfn.XLOOKUP(tblConfigurationAvionics[[#This Row],[Configuration ID]],tblAircraftConfigurations[Configuration ID],tblAircraftConfigurations[Configuration Name],"") -> A321-200 Standard Configuration | E15: =_xlfn.XLOOKUP(tblConfigurationAvionics[[#This Row],[Avionics ID]],tblAvionics[Avionics ID],tblAvionics[System / Model],"") -> Airbus A321 ACARS / CPDLC System | F15: Digital Communications & Data Link System | G15: Primary ToLiss A321 data link system supporting ACARS/CPDLC communications, AOC messaging, ATC data exchange, and operational information services.
A16: 13 | B16: 4 | C16: 13 | D16: =_xlfn.XLOOKUP(tblConfigurationAvionics[[#This Row],[Configuration ID]],tblAircraftConfigurations[Configuration ID],tblAircraftConfigurations[Configuration Name],"") -> A321-200 Standard Configuration | E16: =_xlfn.XLOOKUP(tblConfigurationAvionics[[#This Row],[Avionics ID]],tblAvionics[Avionics ID],tblAvionics[System / Model],"") -> ToLiss A321 Electronic Flight Bag (EFB) | F16: Electronic Flight Bag & Operational Management System | G16: Integrated ToLiss A321 EFB supporting SimBrief OFP integration, weight and balance, takeoff and landing performance, ground services, aircraft configuration, fault scenarios, checklists, and AviTab integration.
... A20: 17 | B20: 4 | C20: 17 | D20: =_xlfn.XLOOKUP(tblConfigurationAvionics[[#This Row],[Configuration ID]],tblAircraftConfigurations[Configuration ID],tblAircraftConfigurations[Configuration Name],"") -> A321-200 Standard Configuration | E20: =_xlfn.XLOOKUP(tblConfigurationAvionics[[#This Row],[Avionics ID]],tblAvionics[Avionics ID],tblAvionics[System / Model],"") -> Airbus A321 GPS / Navigation System | F20: Primary Navigation & Position System | G20: ToLiss A321 navigation implementation supporting GPS-based positioning, flight-plan navigation, waypoint sequencing, radio navigation, and managed lateral navigation through the FMGS.

Sheet Avionics_Evaluations
A1: FSEI Avionics Evaluations Database
A3: Avionics Evaluation ID | B3: Configuration Avionics ID | C3: Configuration ID | D3: Avionics ID | E3: Aircraft | F3: Avionics System | G3: Evaluation Date | H3: Functional Fidelity | I3: Operational / Procedural Fidelity | J3: Display & Interface Fidelity | K3: System Logic & Integration | L3: Navigation Data Handling & Implementation | M3: Failures & Abnormal Behavior | N3: Depth & Edge-Case Fidelity | O3: Fidelity Score | P3: Notes
A4: 1 | B4: 1 | C4: =_xlfn.XLOOKUP(B4,Configuration_Avionics!$A$4:$A$100,Configuration_Avionics!$B$4:$B$100,"") -> 1 | D4: =_xlfn.XLOOKUP(B4,Configuration_Avionics!$A$4:$A$100,Configuration_Avionics!$C$4:$C$100,"") -> 1 | E4: =_xlfn.XLOOKUP(C4,Aircraft_Configurations!$A$4:$A$100,Aircraft_Configurations!$D$4:$D$100,"") -> 777 | F4: =_xlfn.XLOOKUP(D4,Avionics_DB!$A$4:$A$102,Avionics_DB!$D$4:$D$102,"") -> FlightFactor EFB | G4: 46274 | H4: 25 | I4: 20 | J4: 15 | K4: 20 | L4: 8 | M4: 7 | N4: 5 | O4: =IF(COUNT(H4:N5)=0,"",ROUND(SUM(H4:N4)/(IF(H4<>"",25,0)+IF(I4<>"",20,0)+IF(J4<>"",15,0)+IF(K4<>"",20,0)+IF(L4<>"",8,0)+IF(M4<>"",7,0)+IF(N4<>"",5,0))*100,0)) -> 100 | P4: FlightFactor 777v2 EFB evaluated through extensive direct simulator testing and developer documentation. Demonstrated deep integration with flight planning, SimBrief and Navigraph, weight and balance, aircraft loading and boarding, takeoff performance, FMC data, ground and purser services, aircraft initialization, walkaround procedures, communications, failure/maintenance functions, and integrated moving-map capability. The EFB functions as a central operational interface throughout the aircraft workflow rather than as a standalone utility.
A5: 2 | B5: 2 | C5: =_xlfn.XLOOKUP(B5,Configuration_Avionics!$A$4:$A$100,Configuration_Avionics!$B$4:$B$100,"") -> 2 | D5: =_xlfn.XLOOKUP(B5,Configuration_Avionics!$A$4:$A$100,Configuration_Avionics!$C$4:$C$100,"") -> 2 | E5: =_xlfn.XLOOKUP(C5,Aircraft_Configurations!$A$4:$A$100,Aircraft_Configurations!$D$4:$D$100,"") -> SR20 | F5: =_xlfn.XLOOKUP(D5,Avionics_DB!$A$4:$A$102,Avionics_DB!$D$4:$D$102,"") -> Garmin Perspective | G5: 46275 | H5: 24 | I5: 19 | J5: 14 | K5: 20 | L5: 8 | M5: 7 | N5: 5 | O5: =IF(COUNT(H5:N6)=0,"",ROUND(SUM(H5:N5)/(IF(H5<>"",25,0)+IF(I5<>"",20,0)+IF(J5<>"",15,0)+IF(K5<>"",20,0)+IF(L5<>"",8,0)+IF(M5<>"",7,0)+IF(N5<>"",5,0))*100,0)) -> 97 | P5: Functional fidelity scored 24/25 and operational/procedural fidelity 19/20 pending verification of complete Garmin Perspective functionality and workflows. Display/interface fidelity scored 14/15 due to nonfunctional AM/FM radio softkeys. System logic/integration, navigation data handling, failures/abnormal behavior, and depth/edge-case fidelity demonstrated at full-score level through documentation and direct simulator testing.
A6: 3 | B6: 3 | C6: =_xlfn.XLOOKUP(B6,Configuration_Avionics!$A$4:$A$100,Configuration_Avionics!$B$4:$B$100,"") -> 3 | D6: =_xlfn.XLOOKUP(B6,Configuration_Avionics!$A$4:$A$100,Configuration_Avionics!$C$4:$C$100,"") -> 3 | E6: =_xlfn.XLOOKUP(C6,Aircraft_Configurations!$A$4:$A$100,Aircraft_Configurations!$D$4:$D$100,"") -> DA50 | F6: =_xlfn.XLOOKUP(D6,Avionics_DB!$A$4:$A$102,Avionics_DB!$D$4:$D$102,"") -> Garmin G1000 / X1000 | G6: 46276 | H6: 25 | I6: 20 | J6: 15 | K6: 17 | L6: 8 | M6: 6 | N6: 4 | O6: =IF(COUNT(H6:N8)=0,"",ROUND(SUM(H6:N6)/(IF(H6<>"",25,0)+IF(I6<>"",20,0)+IF(J6<>"",15,0)+IF(K6<>"",20,0)+IF(L6<>"",8,0)+IF(M6<>"",7,0)+IF(N6<>"",5,0))*100,0)) -> 95 | P6: Direct testing confirmed strong Garmin G1000/X1000 functional, operational, display/interface, navigation, failure, and aircraft-system integration fidelity. ILS RWY 11 at KCAE loaded and displayed the correct 112° final course; a repeat approach ultimately tracked the runway centerline correctly. Testing identified a significant autoflight limitation in selected-altitude capture: with 2,500 ft selected, the aircraft substantially overshot the commanded altitude before correcting. Breaker testing demonstrated functional MFD power isolation and multiple aircraft-system consequences, although some tested breakers produced no observable downstream avionics failure and MFD recovery after breaker reset was simplified. These findings resulted in deductions to System Logic & Integration, Failures & Abnormal Behavior, and Depth & Edge-Case Fidelity. Independent pilot-reported engine-start procedural differences are treated as aircraft systems/procedural evidence and are excluded from this avionics score.
A7: 4 | B7: 4 | C7: =_xlfn.XLOOKUP(B7,Configuration_Avionics!$A$4:$A$100,Configuration_Avionics!$B$4:$B$100,"") -> 1 | D7: =_xlfn.XLOOKUP(B7,Configuration_Avionics!$A$4:$A$100,Configuration_Avionics!$C$4:$C$100,"") -> 4 | E7: =_xlfn.XLOOKUP(C7,Aircraft_Configurations!$A$4:$A$100,Aircraft_Configurations!$D$4:$D$100,"") -> 777 | F7: =_xlfn.XLOOKUP(D7,Avionics_DB!$A$4:$A$102,Avionics_DB!$D$4:$D$102,"") -> 777 Flight Management System (FMS/FMC) | G7: 46276 | H7: 25 | I7: 20 | J7: 15 | K7: 20 | L7: 8 | M7: 7 | N7: 5 | O7: =IF(COUNT(H7:N10)=0,"",ROUND(SUM(H7:N7)/(IF(H7<>"",25,0)+IF(I7<>"",20,0)+IF(J7<>"",15,0)+IF(K7<>"",20,0)+IF(L7<>"",8,0)+IF(M7<>"",7,0)+IF(N7<>"",5,0))*100,0)) -> 100 | P7: FlightFactor 777v2 FMS/FMC evaluated through direct simulator testing and developer documentation. Demonstrated high-fidelity flight planning, performance initialization, SID/STAR and runway modification, wind and forecast uplinks, navigation-data handling, and integration with aircraft systems and the EFB throughout normal flight operations.
A8: 5 | B8: 5 | C8: =_xlfn.XLOOKUP(B8,Configuration_Avionics!$A$4:$A$100,Configuration_Avionics!$B$4:$B$100,"") -> 1 | D8: =_xlfn.XLOOKUP(B8,Configuration_Avionics!$A$4:$A$100,Configuration_Avionics!$C$4:$C$100,"") -> 5 | E8: =_xlfn.XLOOKUP(C8,Aircraft_Configurations!$A$4:$A$100,Aircraft_Configurations!$D$4:$D$100,"") -> 777 | F8: =_xlfn.XLOOKUP(D8,Avionics_DB!$A$4:$A$102,Avionics_DB!$D$4:$D$102,"") -> 777 Primary Flight & Navigation Display System | G8: 46276 | H8: 25 | I8: 20 | J8: 15 | K8: 20 | L8: 8 | M8: 7 | N8: 5 | O8: =IF(COUNT(H8:N12)=0,"",ROUND(SUM(H8:N8)/(IF(H8<>"",25,0)+IF(I8<>"",20,0)+IF(J8<>"",15,0)+IF(K8<>"",20,0)+IF(L8<>"",8,0)+IF(M8<>"",7,0)+IF(N8<>"",5,0))*100,0)) -> 100 | P8: FlightFactor 777v2 PFD/ND evaluated through direct simulator testing and developer documentation. Demonstrated high-fidelity primary flight and navigation displays, flight-mode annunciations, route and waypoint presentation, managed navigation information, approach guidance, and integration with the FMS and autoflight systems throughout normal flight operations.
A9: 6 | B9: 6 | C9: =_xlfn.XLOOKUP(B9,Configuration_Avionics!$A$4:$A$100,Configuration_Avionics!$B$4:$B$100,"") -> 1 | D9: =_xlfn.XLOOKUP(B9,Configuration_Avionics!$A$4:$A$100,Configuration_Avionics!$C$4:$C$100,"") -> 6 | E9: =_xlfn.XLOOKUP(C9,Aircraft_Configurations!$A$4:$A$100,Aircraft_Configurations!$D$4:$D$100,"") -> 777 | F9: =_xlfn.XLOOKUP(D9,Avionics_DB!$A$4:$A$102,Avionics_DB!$D$4:$D$102,"") -> 777 Center Multifunction Display System | G9: 46276 | H9: 25 | I9: 20 | J9: 15 | K9: 20 | L9: 8 | M9: 7 | N9: 5 | O9: =IF(COUNT(H9:N14)=0,"",ROUND(SUM(H9:N9)/(IF(H9<>"",25,0)+IF(I9<>"",20,0)+IF(J9<>"",15,0)+IF(K9<>"",20,0)+IF(L9<>"",8,0)+IF(M9<>"",7,0)+IF(N9<>"",5,0))*100,0)) -> 100 | P9: FlightFactor 777v2 Center Multifunction Display evaluated through direct simulator testing and developer documentation. Demonstrated detailed aircraft systems monitoring and display integration, including secondary flight-display/reversion capability. Integrated with the aircraft’s extensive failure and abnormal-condition architecture, providing system status and operational information across normal and abnormal operations.
A10: 7 | B10: 7 | C10: =_xlfn.XLOOKUP(B10,Configuration_Avionics!$A$4:$A$100,Configuration_Avionics!$B$4:$B$100,"") -> 1 | D10: =_xlfn.XLOOKUP(B10,Configuration_Avionics!$A$4:$A$100,Configuration_Avionics!$C$4:$C$100,"") -> 7 | E10: =_xlfn.XLOOKUP(C10,Aircraft_Configurations!$A$4:$A$100,Aircraft_Configurations!$D$4:$D$100,"") -> 777 | F10: =_xlfn.XLOOKUP(D10,Avionics_DB!$A$4:$A$102,Avionics_DB!$D$4:$D$102,"") -> 777 Autoflight / Flight Director System | G10: 46276 | H10: 25 | I10: 20 | J10: 15 | K10: 20 | L10: 8 | M10: 7 | N10: 5 | O10: =IF(COUNT(H10:N16)=0,"",ROUND(SUM(H10:N10)/(IF(H10<>"",25,0)+IF(I10<>"",20,0)+IF(J10<>"",15,0)+IF(K10<>"",20,0)+IF(L10<>"",8,0)+IF(M10<>"",7,0)+IF(N10<>"",5,0))*100,0)) -> 100 | P10: FlightFactor 777v2 Autoflight / Flight Director System evaluated through direct simulator testing and developer documentation. Demonstrated high-fidelity managed and selected flight guidance, flight-director commands, autopilot operation, FMS integration, mode annunciation and approach/landing guidance, including integrated autoflight behavior throughout normal flight operations.
A11: 8 | B11: 8 | C11: =_xlfn.XLOOKUP(B11,Configuration_Avionics!$A$4:$A$100,Configuration_Avionics!$B$4:$B$100,"") -> 4 | D11: =_xlfn.XLOOKUP(B11,Configuration_Avionics!$A$4:$A$100,Configuration_Avionics!$C$4:$C$100,"") -> 8 | E11: =_xlfn.XLOOKUP(C11,Aircraft_Configurations!$A$4:$A$100,Aircraft_Configurations!$D$4:$D$100,"") -> A321 | F11: =_xlfn.XLOOKUP(D11,Avionics_DB!$A$4:$A$102,Avionics_DB!$D$4:$D$102,"") -> Airbus A321 Flight Management and Guidance System (FMGS) | G11: 46281 | H11: 25 | I11: 20 | J11: 15 | K11: 20 | L11: 8 | M11: 7 | N11: 5 | O11: =IF(COUNT(H11:N18)=0,"",ROUND(SUM(H11:N11)/(IF(H11<>"",25,0)+IF(I11<>"",20,0)+IF(J11<>"",15,0)+IF(K11<>"",20,0)+IF(L11<>"",8,0)+IF(M11<>"",7,0)+IF(N11<>"",5,0))*100,0)) -> 100 | P11: ToLiss A321 FMGS evaluated through direct simulator testing and official ToLiss documentation. Demonstrated high-fidelity flight-plan management, performance initialization, SID/STAR and runway procedures, managed and selected guidance, wind and performance data handling, navigation functions, and integration with the aircraft’s autoflight, display, and EFB systems throughout a complete KCLT–KLAF flight.
A12: 9 | B12: 9 | C12: =_xlfn.XLOOKUP(B12,Configuration_Avionics!$A$4:$A$100,Configuration_Avionics!$B$4:$B$100,"") -> 4 | D12: =_xlfn.XLOOKUP(B12,Configuration_Avionics!$A$4:$A$100,Configuration_Avionics!$C$4:$C$100,"") -> 9 | E12: =_xlfn.XLOOKUP(C12,Aircraft_Configurations!$A$4:$A$100,Aircraft_Configurations!$D$4:$D$100,"") -> A321 | F12: =_xlfn.XLOOKUP(D12,Avionics_DB!$A$4:$A$102,Avionics_DB!$D$4:$D$102,"") -> Airbus A321 Autopilot / Flight Director System | G12: 46281 | H12: 25 | I12: 20 | J12: 15 | K12: 20 | L12: 8 | M12: 7 | N12: 5 | O12: =IF(COUNT(H12:N20)=0,"",ROUND(SUM(H12:N12)/(IF(H12<>"",25,0)+IF(I12<>"",20,0)+IF(J12<>"",15,0)+IF(K12<>"",20,0)+IF(L12<>"",8,0)+IF(M12<>"",7,0)+IF(N12<>"",5,0))*100,0)) -> 100 | P12: ToLiss A321 Autopilot / Flight Director System evaluated through direct simulator testing and official ToLiss documentation. Demonstrated high-fidelity managed and selected guidance, flight director commands, autopilot operation, mode annunciation, FMGS integration, and approach/landing guidance, including dual-autopilot CAT III operation during the complete KCLT–KLAF evaluation flight.
A13: 10 | B13: 10 | C13: =_xlfn.XLOOKUP(B13,Configuration_Avionics!$A$4:$A$100,Configuration_Avionics!$B$4:$B$100,"") -> 4 | D13: =_xlfn.XLOOKUP(B13,Configuration_Avionics!$A$4:$A$100,Configuration_Avionics!$C$4:$C$100,"") -> 10 | E13: =_xlfn.XLOOKUP(C13,Aircraft_Configurations!$A$4:$A$100,Aircraft_Configurations!$D$4:$D$100,"") -> A321 | F13: =_xlfn.XLOOKUP(D13,Avionics_DB!$A$4:$A$102,Avionics_DB!$D$4:$D$102,"") -> Airbus A321 Primary Flight / Navigation Display System | G13: 46281 | H13: 25 | I13: 20 | J13: 15 | K13: 20 | L13: 8 | M13: 7 | N13: 5 | O13: =IF(COUNT(H13:N22)=0,"",ROUND(SUM(H13:N13)/(IF(H13<>"",25,0)+IF(I13<>"",20,0)+IF(J13<>"",15,0)+IF(K13<>"",20,0)+IF(L13<>"",8,0)+IF(M13<>"",7,0)+IF(N13<>"",5,0))*100,0)) -> 100 | P13: ToLiss A321 PFD/ND evaluated through direct simulator testing and official ToLiss documentation. Demonstrated high-fidelity primary flight and navigation presentation, flight-mode annunciations, managed and selected guidance, route and waypoint display, weather/terrain information, approach guidance, and integration with the FMGS and autoflight systems throughout the complete KCLT–KLAF evaluation flight.
A14: 11 | B14: 11 | C14: =_xlfn.XLOOKUP(B14,Configuration_Avionics!$A$4:$A$100,Configuration_Avionics!$B$4:$B$100,"") -> 4 | D14: =_xlfn.XLOOKUP(B14,Configuration_Avionics!$A$4:$A$100,Configuration_Avionics!$C$4:$C$100,"") -> 11 | E14: =_xlfn.XLOOKUP(C14,Aircraft_Configurations!$A$4:$A$100,Aircraft_Configurations!$D$4:$D$100,"") -> A321 | F14: =_xlfn.XLOOKUP(D14,Avionics_DB!$A$4:$A$102,Avionics_DB!$D$4:$D$102,"") -> Airbus A321 ECAM Engine Warning / System Display System | G14: 46281 | H14: 25 | I14: 20 | J14: 15 | K14: 20 | L14: 8 | M14: 7 | N14: 5 | O14: =IF(COUNT(H14:N24)=0,"",ROUND(SUM(H14:N14)/(IF(H14<>"",25,0)+IF(I14<>"",20,0)+IF(J14<>"",15,0)+IF(K14<>"",20,0)+IF(L14<>"",8,0)+IF(M14<>"",7,0)+IF(N14<>"",5,0))*100,0)) -> 100 | P14: ToLiss A321 ECAM evaluated through direct simulator testing and official ToLiss documentation. Demonstrated high-fidelity engine and warning presentation, aircraft systems monitoring, system synoptic displays, status information, alerting logic, and integration with aircraft systems and abnormal-condition handling throughout normal flight operations.
A15: 12 | B15: 12 | C15: =_xlfn.XLOOKUP(B15,Configuration_Avionics!$A$4:$A$100,Configuration_Avionics!$B$4:$B$100,"") -> 4 | D15: =_xlfn.XLOOKUP(B15,Configuration_Avionics!$A$4:$A$100,Configuration_Avionics!$C$4:$C$100,"") -> 12 | E15: =_xlfn.XLOOKUP(C15,Aircraft_Configurations!$A$4:$A$100,Aircraft_Configurations!$D$4:$D$100,"") -> A321 | F15: =_xlfn.XLOOKUP(D15,Avionics_DB!$A$4:$A$102,Avionics_DB!$D$4:$D$102,"") -> Airbus A321 ACARS / CPDLC System | G15: 46281 | H15: 25 | I15: 20 | J15: 15 | K15: 20 | L15: 8 | M15: 7 | N15: 5 | O15: =IF(COUNT(H15:N26)=0,"",ROUND(SUM(H15:N15)/(IF(H15<>"",25,0)+IF(I15<>"",20,0)+IF(J15<>"",15,0)+IF(K15<>"",20,0)+IF(L15<>"",8,0)+IF(M15<>"",7,0)+IF(N15<>"",5,0))*100,0)) -> 100 | P15: ToLiss A321 ACARS/CPDLC system evaluated through direct simulator testing and official ToLiss documentation. Demonstrated integrated digital communications supporting CPDLC, AOC messaging, ATC data exchange, flight-plan and operational information services, with integration into the aircraft’s FMGS and communications environment throughout normal flight operations.
A16: 13 | B16: 13 | C16: =_xlfn.XLOOKUP(B16,Configuration_Avionics!$A$4:$A$100,Configuration_Avionics!$B$4:$B$100,"") -> 4 | D16: =_xlfn.XLOOKUP(B16,Configuration_Avionics!$A$4:$A$100,Configuration_Avionics!$C$4:$C$100,"") -> 13 | E16: =_xlfn.XLOOKUP(C16,Aircraft_Configurations!$A$4:$A$100,Aircraft_Configurations!$D$4:$D$100,"") -> A321 | F16: =_xlfn.XLOOKUP(D16,Avionics_DB!$A$4:$A$102,Avionics_DB!$D$4:$D$102,"") -> ToLiss A321 Electronic Flight Bag (EFB) | G16: 46281 | H16: 25 | I16: 20 | J16: 15 | K16: 20 | L16: 7 | M16: 7 | N16: 5 | O16: =IF(COUNT(H16:N28)=0,"",ROUND(SUM(H16:N16)/(IF(H16<>"",25,0)+IF(I16<>"",20,0)+IF(J16<>"",15,0)+IF(K16<>"",20,0)+IF(L16<>"",8,0)+IF(M16<>"",7,0)+IF(N16<>"",5,0))*100,0)) -> 99 | P16: ToLiss A321 EFB evaluated through direct simulator testing and official ToLiss documentation. Demonstrated deep integration with SimBrief OFP data, weight and balance, takeoff and landing performance, ground services, aircraft configuration, checklists, Navigraph/AviTab, and ISCS functions. Failure functionality includes more than 200 injectable failures, MTBF-based random failures, simultaneous fault combinations, failure propagation, and configurable fault scenarios accessible through the integrated ISCS environment. ToLiss_AirbusA321_SimulationManual.pdfPDF
A17: 14 | B17: 14 | C17: =_xlfn.XLOOKUP(B17,Configuration_Avionics!$A$4:$A$100,Configuration_Avionics!$B$4:$B$100,"") -> 4 | D17: =_xlfn.XLOOKUP(B17,Configuration_Avionics!$A$4:$A$100,Configuration_Avionics!$C$4:$C$100,"") -> 14 | E17: =_xlfn.XLOOKUP(C17,Aircraft_Configurations!$A$4:$A$100,Aircraft_Configurations!$D$4:$D$100,"") -> A321 | F17: =_xlfn.XLOOKUP(D17,Avionics_DB!$A$4:$A$102,Avionics_DB!$D$4:$D$102,"") -> Airbus A321 Weather Radar System | G17: 46281 | H17: 25 | I17: 20 | J17: 15 | K17: 20 | L17: 6 | M17: 6 | N17: 4 | O17: =IF(COUNT(H17:N30)=0,"",ROUND(SUM(H17:N17)/(IF(H17<>"",25,0)+IF(I17<>"",20,0)+IF(J17<>"",15,0)+IF(K17<>"",20,0)+IF(L17<>"",8,0)+IF(M17<>"",7,0)+IF(N17<>"",5,0))*100,0)) -> 96 | P17: ToLiss A321 Weather Radar evaluated through direct simulator testing and official documentation. During departure and climb, the aircraft encountered a significant weather formation extending to approximately 27,000 feet; the navigation display showed a solid red weather-radar return while penetrating the storm area, with the aircraft experiencing substantial difficulty maintaining course in the associated conditions. Radar returns cleared after exiting the weather, providing direct operational evidence of weather detection, display presentation, and aircraft-system integration.
A18: 15 | B18: 15 | C18: =_xlfn.XLOOKUP(B18,Configuration_Avionics!$A$4:$A$100,Configuration_Avionics!$B$4:$B$100,"") -> 4 | D18: =_xlfn.XLOOKUP(B18,Configuration_Avionics!$A$4:$A$100,Configuration_Avionics!$C$4:$C$100,"") -> 15 | E18: =_xlfn.XLOOKUP(C18,Aircraft_Configurations!$A$4:$A$100,Aircraft_Configurations!$D$4:$D$100,"") -> A321 | F18: =_xlfn.XLOOKUP(D18,Avionics_DB!$A$4:$A$102,Avionics_DB!$D$4:$D$102,"") -> Airbus A321 Traffic Alert and Collision Avoidance System (TCAS) | G18: 46281 | H18: 25 | I18: 20 | J18: 15 | K18: 20 | L18: 8 | M18: 7 | N18: 5 | O18: =IF(COUNT(H18:N32)=0,"",ROUND(SUM(H18:N18)/(IF(H18<>"",25,0)+IF(I18<>"",20,0)+IF(J18<>"",15,0)+IF(K18<>"",20,0)+IF(L18<>"",8,0)+IF(M18<>"",7,0)+IF(N18<>"",5,0))*100,0)) -> 100
A19: 16 | B19: 16 | C19: =_xlfn.XLOOKUP(B19,Configuration_Avionics!$A$4:$A$100,Configuration_Avionics!$B$4:$B$100,"") -> 4 | D19: =_xlfn.XLOOKUP(B19,Configuration_Avionics!$A$4:$A$100,Configuration_Avionics!$C$4:$C$100,"") -> 16 | E19: =_xlfn.XLOOKUP(C19,Aircraft_Configurations!$A$4:$A$100,Aircraft_Configurations!$D$4:$D$100,"") -> A321 | F19: =_xlfn.XLOOKUP(D19,Avionics_DB!$A$4:$A$102,Avionics_DB!$D$4:$D$102,"") -> Airbus A321 Terrain Awareness and Warning System (TAWS/EGPWS) | G19: 46281 | H19: 24 | I19: 19 | J19: 14 | K19: 19 | L19: 8 | M19: 6 | N19: 4 | O19: =IF(COUNT(H19:N34)=0,"",ROUND(SUM(H19:N19)/(IF(H19<>"",25,0)+IF(I19<>"",20,0)+IF(J19<>"",15,0)+IF(K19<>"",20,0)+IF(L19<>"",8,0)+IF(M19<>"",7,0)+IF(N19<>"",5,0))*100,0)) -> 94 | P19: ToLiss A321 TAWS/EGPWS evaluated through direct simulator operation and official documentation. Demonstrated integrated terrain awareness and terrain presentation using aircraft position and navigation data, with terrain information incorporated into the flight-deck display environment. Full terrain-warning, abnormal, and edge-case scenarios were not deliberately triggered during the evaluation flight and remain candidates for additional direct testing.
A20: 17 | B20: 17 | C20: =_xlfn.XLOOKUP(B20,Configuration_Avionics!$A$4:$A$100,Configuration_Avionics!$B$4:$B$100,"") -> 4 | D20: =_xlfn.XLOOKUP(B20,Configuration_Avionics!$A$4:$A$100,Configuration_Avionics!$C$4:$C$100,"") -> 17 | E20: =_xlfn.XLOOKUP(C20,Aircraft_Configurations!$A$4:$A$100,Aircraft_Configurations!$D$4:$D$100,"") -> A321 | F20: =_xlfn.XLOOKUP(D20,Avionics_DB!$A$4:$A$102,Avionics_DB!$D$4:$D$102,"") -> Airbus A321 GPS / Navigation System | G20: 46281 | H20: 25 | I20: 20 | J20: 15 | K20: 20 | L20: 8 | M20: 6 | N20: 4 | O20: =IF(COUNT(H20:N36)=0,"",ROUND(SUM(H20:N20)/(IF(H20<>"",25,0)+IF(I20<>"",20,0)+IF(J20<>"",15,0)+IF(K20<>"",20,0)+IF(L20<>"",8,0)+IF(M20<>"",7,0)+IF(N20<>"",5,0))*100,0)) -> 98 | P20: ToLiss A321 GPS / Navigation System evaluated through direct simulator testing and official documentation. Demonstrated high-fidelity aircraft positioning, route and waypoint sequencing, SID/STAR and approach procedure handling, navigation-data processing, and integration with the FMGS, navigation display, and autoflight systems throughout the complete KCLT–KLAF evaluation flight. Normal navigation functionality was extensively demonstrated; degraded GPS, navigation-sensor failures, and unusual navigation edge cases remain candidates for additional direct testing.

Sheet Avionics_Evaluation_Sources
A1: FSEI Avionics Evaluation Sources DB
A3: Avionics Evaluation Source ID | B3: Avionics Evaluation ID | C3: Source ID | D3: Aircraft | E3: Avionics System | F3: Evidence Role | G3: Notes
A4: 1 | B4: 1 | C4: 1 | D4: =_xlfn.XLOOKUP(B4,Avionics_Evaluations!$A$4:$A$100,Avionics_Evaluations!$E$4:$E$100,"") -> 777 | E4: =_xlfn.XLOOKUP(B4,Avionics_Evaluations!$A$4:$A$100,Avionics_Evaluations!$F$4:$F$100,"") -> FlightFactor EFB | F4: Primary | G4: Primary developer documentation supporting the documented functionality and capabilities of the FlightFactor 777 EFB.
A5: 2 | B5: 1 | C5: 7 | D5: =_xlfn.XLOOKUP(B5,Avionics_Evaluations!$A$4:$A$100,Avionics_Evaluations!$E$4:$E$100,"") -> 777 | E5: =_xlfn.XLOOKUP(B5,Avionics_Evaluations!$A$4:$A$100,Avionics_Evaluations!$F$4:$F$100,"") -> FlightFactor EFB | F5: Supporting | G5: Supporting cockpit documentation for avionics displays, controls, indications, and system interfaces.
A6: 3 | B6: 1 | C6: 8 | D6: =_xlfn.XLOOKUP(B6,Avionics_Evaluations!$A$4:$A$100,Avionics_Evaluations!$E$4:$E$100,"") -> 777 | E6: =_xlfn.XLOOKUP(B6,Avionics_Evaluations!$A$4:$A$100,Avionics_Evaluations!$F$4:$F$100,"") -> FlightFactor EFB | F6: Supporting | G6: Supporting evidence for procedural implementation, interactive procedures, checklists, and crew-interaction behavior.
A7: 4 | B7: 1 | C7: 10 | D7: =_xlfn.XLOOKUP(B7,Avionics_Evaluations!$A$4:$A$100,Avionics_Evaluations!$E$4:$E$100,"") -> 777 | E7: =_xlfn.XLOOKUP(B7,Avionics_Evaluations!$A$4:$A$100,Avionics_Evaluations!$F$4:$F$100,"") -> FlightFactor EFB | F7: Direct Testing | G7: Hands-on XP12 testing supporting the avionics fidelity score, including system interaction, failure behavior, and observed operational limitations.
A8: 5 | B8: 2 | C8: 11 | D8: =_xlfn.XLOOKUP(B8,Avionics_Evaluations!$A$4:$A$100,Avionics_Evaluations!$E$4:$E$100,"") -> SR20 | E8: =_xlfn.XLOOKUP(B8,Avionics_Evaluations!$A$4:$A$100,Avionics_Evaluations!$F$4:$F$100,"") -> Garmin Perspective | F8: Primary | G8: Primary aircraft documentation supporting evaluation of Garmin Perspective avionics functionality, procedures, system integration, electrical behavior, annunciations, and abnormal operations in the TorqueSim SR20 G3.
A9: 6 | B9: 2 | C9: 12 | D9: =_xlfn.XLOOKUP(B9,Avionics_Evaluations!$A$4:$A$100,Avionics_Evaluations!$E$4:$E$100,"") -> SR20 | E9: =_xlfn.XLOOKUP(B9,Avionics_Evaluations!$A$4:$A$100,Avionics_Evaluations!$F$4:$F$100,"") -> Garmin Perspective | F9: Direct Testing | G9: Direct hands-on testing supporting the Garmin Perspective evaluation, including IFR procedures, electrical and circuit-breaker interactions, annunciation behavior, navigation operation, abnormal navigation/heading behavior, and RNAV approach operations.
A10: 7 | B10: 3 | C10: 13 | D10: =_xlfn.XLOOKUP(B10,Avionics_Evaluations!$A$4:$A$100,Avionics_Evaluations!$E$4:$E$100,"") -> DA50 | E10: =_xlfn.XLOOKUP(B10,Avionics_Evaluations!$A$4:$A$100,Avionics_Evaluations!$F$4:$F$100,"") -> Garmin G1000 / X1000 | F10: Direct Testing | G10: Primary Aerobask aircraft documentation supporting evaluation of the DA50 RG Garmin G1000/X1000 avionics implementation, functionality, integration, procedures, and modeled systems.
A11: 8 | B11: 3 | C11: 14 | D11: =_xlfn.XLOOKUP(B11,Avionics_Evaluations!$A$4:$A$100,Avionics_Evaluations!$E$4:$E$100,"") -> DA50 | E11: =_xlfn.XLOOKUP(B11,Avionics_Evaluations!$A$4:$A$100,Avionics_Evaluations!$F$4:$F$100,"") -> Garmin G1000 / X1000 | F11: Direct Testing | G11: Direct hands-on testing supporting evaluation of the DA50 RG Garmin G1000/X1000 avionics functionality, procedures, system integration, failures and abnormal behavior, and edge-case fidelity.
A12: 9 | B12: 4 | C12: 16 | D12: =_xlfn.XLOOKUP(B12,Avionics_Evaluations!$A$4:$A$100,Avionics_Evaluations!$E$4:$E$100,"") -> 777 | E12: =_xlfn.XLOOKUP(B12,Avionics_Evaluations!$A$4:$A$100,Avionics_Evaluations!$F$4:$F$100,"") -> 777 Flight Management System (FMS/FMC) | F12: Supporting | G12: FF 777 Introduction Bulletin
A13: 10 | B13: 4 | C13: 16 | D13: =_xlfn.XLOOKUP(B13,Avionics_Evaluations!$A$4:$A$100,Avionics_Evaluations!$E$4:$E$100,"") -> 777 | E13: =_xlfn.XLOOKUP(B13,Avionics_Evaluations!$A$4:$A$100,Avionics_Evaluations!$F$4:$F$100,"") -> 777 Flight Management System (FMS/FMC) | F13: Supporting | G13: FF 777Cockpit Guide
A14: 11 | B14: 4 | C14: 16 | D14: =_xlfn.XLOOKUP(B14,Avionics_Evaluations!$A$4:$A$100,Avionics_Evaluations!$E$4:$E$100,"") -> 777 | E14: =_xlfn.XLOOKUP(B14,Avionics_Evaluations!$A$4:$A$100,Avionics_Evaluations!$F$4:$F$100,"") -> 777 Flight Management System (FMS/FMC) | F14: Supporting | G14: FF777 Remote Instrumentation Manual
A15: 12 | B15: 4 | C15: 16 | D15: =_xlfn.XLOOKUP(B15,Avionics_Evaluations!$A$4:$A$100,Avionics_Evaluations!$E$4:$E$100,"") -> 777 | E15: =_xlfn.XLOOKUP(B15,Avionics_Evaluations!$A$4:$A$100,Avionics_Evaluations!$F$4:$F$100,"") -> 777 Flight Management System (FMS/FMC) | F15: Direct Testing | G15: FF 777 FMS/FMC Direct Testing

Sheet ---- EVIDENCE ----

Sheet Sources_DB
A1: FSEI Sources Database
A3: Source ID | B3: Aircraft ID | C3: Variant ID | D3: Variant | E3: Evidence Scope | F3: Aircraft | G3: Simulator | H3: Source Type | I3: Source Name | J3: Source URL | K3: Date Assessed | L3: Notes | M3: Date Verified | N3: Active Source
A4: 1 | B4: 1 | C4: 1 | D4: =IF(tblSources[[#This Row],[Variant ID]]="","",_xlfn.XLOOKUP(tblSources[[#This Row],[Variant ID]],tblAircraftVariants[Variant ID],tblAircraftVariants[Variant],"")) -> 777-200ER | E4: General Product Documentation | F4: =_xlfn.XLOOKUP(tblSources[[#This Row],[Aircraft ID]],tblAircraft[Aircraft ID],tblAircraft[Aircraft],"") -> 777 | G4: =_xlfn.XLOOKUP(tblSources[[#This Row],[Aircraft ID]],tblAircraft[Aircraft ID],tblAircraft[Simulator],"") -> X-Plane 12 | H4: Developer Documentation | I4: FlightFactor 777 v2 Product Documentation | K4: 46274 | M4: 46274 | N4: Yes
A5: 2 | B5: 1 | D5: =IF(tblSources[[#This Row],[Variant ID]]="","",_xlfn.XLOOKUP(tblSources[[#This Row],[Variant ID]],tblAircraftVariants[Variant ID],tblAircraftVariants[Variant],"")) | E5: General Product Documentation | F5: =_xlfn.XLOOKUP(tblSources[[#This Row],[Aircraft ID]],tblAircraft[Aircraft ID],tblAircraft[Aircraft],"") -> 777 | G5: =_xlfn.XLOOKUP(tblSources[[#This Row],[Aircraft ID]],tblAircraft[Aircraft ID],tblAircraft[Simulator],"") -> X-Plane 12 | H5: Aircraft Manual | I5: FlightFactor 777 Ultimate Introduction Bulletin | K5: 46274 | L5: Primary developer manual covering 777 Ultimate model, simulation features, EFB, maintenance, failures, training, ACARS/CPDLC, and operational features. | M5: 46274 | N5: Yes
A6: 3 | B6: 1 | C6: 1 | D6: =IF(tblSources[[#This Row],[Variant ID]]="","",_xlfn.XLOOKUP(tblSources[[#This Row],[Variant ID]],tblAircraftVariants[Variant ID],tblAircraftVariants[Variant],"")) -> 777-200ER | E6: Engine / Variant Combination | F6: =_xlfn.XLOOKUP(tblSources[[#This Row],[Aircraft ID]],tblAircraft[Aircraft ID],tblAircraft[Aircraft],"") -> 777 | G6: =_xlfn.XLOOKUP(tblSources[[#This Row],[Aircraft ID]],tblAircraft[Aircraft ID],tblAircraft[Simulator],"") -> X-Plane 12 | H6: Aircraft Manual | I6: Performance and Flight Model - B777-200ER GE90-90B | K6: 46274 | L6: Developer performance and flight-model validation document for the B777-200ER GE90-90B; includes validation methodology, flight-envelope testing, performance comparisons, and XP12-specific tuning. | M6: 46274 | N6: Yes
A7: 4 | B7: 1 | C7: 2 | D7: =IF(tblSources[[#This Row],[Variant ID]]="","",_xlfn.XLOOKUP(tblSources[[#This Row],[Variant ID]],tblAircraftVariants[Variant ID],tblAircraftVariants[Variant],"")) -> 777-300ER | E7: Engine / Variant Combination | F7: =_xlfn.XLOOKUP(tblSources[[#This Row],[Aircraft ID]],tblAircraft[Aircraft ID],tblAircraft[Aircraft],"") -> 777 | G7: =_xlfn.XLOOKUP(tblSources[[#This Row],[Aircraft ID]],tblAircraft[Aircraft ID],tblAircraft[Simulator],"") -> X-Plane 12 | H7: Aircraft Manual | I7: Performance and Flight Model - B777-300ER GE90-115BL | K7: 46274 | L7: Developer performance and flight-model validation document for the B777-300ER GE90-115BL; includes validation methodology, flight-envelope testing, performance comparisons, and XP12-specific tuning. | M7: 46274 | N7: Yes
